<?xml version="1.0" encoding="UTF-8"?>
<!-- Generated by org.testng.reporters.JUnitXMLReporter -->
<testsuite hostname="Noak-pc" name="test.cli.cloudify" tests="34" failures="13" timestamp="2 Jan 2012 12:34:28 GMT" time="450.279" errors="0">
  <testcase name="@BeforeMethod beforeTest" time="0.0" classname="test.cli.cloudify.AdminApiControllerTest">
    <failure type="java.lang.AssertionError">
      <![CDATA[java.lang.AssertionError: 
	at org.testng.AssertJUnit.fail(AssertJUnit.java:59)
	at org.testng.AssertJUnit.assertTrue(AssertJUnit.java:24)
	at org.testng.AssertJUnit.assertNotNull(AssertJUnit.java:267)
	at org.testng.AssertJUnit.assertNotNull(AssertJUnit.java:259)
	at framework.utils.SetupUtils.assertCleanSetup(SetupUtils.java:61)
	at framework.utils.SetupUtils.assertCleanSetup(SetupUtils.java:51)
	at test.AbstractTest.beforeTest(AbstractTest.java:30)
	at test.cli.cloudify.AbstractCommandTest.beforeTest(AbstractCommandTest.java:37)
	at test.cli.cloudify.AdminApiControllerTest.beforeTest(AdminApiControllerTest.java:31)
	at sun.reflect.NativeMethodAccessorImpl.invoke0(Native Method)
	at sun.reflect.NativeMethodAccessorImpl.invoke(Unknown Source)
	at sun.reflect.DelegatingMethodAccessorImpl.invoke(Unknown Source)
	at java.lang.reflect.Method.invoke(Unknown Source)
	at org.testng.internal.MethodInvocationHelper.invokeMethod(MethodInvocationHelper.java:80)
	at org.testng.internal.Invoker.invokeConfigurationMethod(Invoker.java:543)
	at org.testng.internal.Invoker.invokeConfigurations(Invoker.java:212)
	at org.testng.internal.Invoker.invokeMethod(Invoker.java:631)
	at org.testng.internal.Invoker.invokeTestMethod(Invoker.java:883)
	at org.testng.internal.Invoker.invokeTestMethods(Invoker.java:1208)
	at org.testng.internal.TestMethodWorker.invokeTestMethods(TestMethodWorker.java:127)
	at org.testng.internal.TestMethodWorker.run(TestMethodWorker.java:111)
	at org.testng.TestRunner.privateRun(TestRunner.java:758)
	at org.testng.TestRunner.run(TestRunner.java:613)
	at org.testng.SuiteRunner.runTest(SuiteRunner.java:334)
	at org.testng.SuiteRunner.runSequentially(SuiteRunner.java:329)
	at org.testng.SuiteRunner.privateRun(SuiteRunner.java:291)
	at org.testng.SuiteRunner.run(SuiteRunner.java:240)
	at org.testng.SuiteRunnerWorker.runSuite(SuiteRunnerWorker.java:53)
	at org.testng.SuiteRunnerWorker.run(SuiteRunnerWorker.java:87)
	at org.testng.TestNG.runSuitesSequentially(TestNG.java:1142)
	at org.testng.TestNG.runSuitesLocally(TestNG.java:1067)
	at org.testng.TestNG.run(TestNG.java:979)
	at org.testng.remote.RemoteTestNG.run(RemoteTestNG.java:109)
	at org.testng.remote.RemoteTestNG.initAndRun(RemoteTestNG.java:202)
	at org.testng.remote.RemoteTestNG.main(RemoteTestNG.java:173)
]]>
    </failure>
  </testcase>
  <testcase name="@BeforeMethod beforeTest" time="0.0" classname="test.cli.cloudify.BadUSMServiceDownAfterUninstallApplicationTest">
    <failure type="java.lang.AssertionError">
      <![CDATA[java.lang.AssertionError: 
	at org.testng.AssertJUnit.fail(AssertJUnit.java:59)
	at org.testng.AssertJUnit.assertTrue(AssertJUnit.java:24)
	at org.testng.AssertJUnit.assertNotNull(AssertJUnit.java:267)
	at org.testng.AssertJUnit.assertNotNull(AssertJUnit.java:259)
	at framework.utils.SetupUtils.assertCleanSetup(SetupUtils.java:61)
	at framework.utils.SetupUtils.assertCleanSetup(SetupUtils.java:51)
	at test.AbstractTest.beforeTest(AbstractTest.java:30)
	at test.cli.cloudify.AbstractCommandTest.beforeTest(AbstractCommandTest.java:37)
	at sun.reflect.NativeMethodAccessorImpl.invoke0(Native Method)
	at sun.reflect.NativeMethodAccessorImpl.invoke(Unknown Source)
	at sun.reflect.DelegatingMethodAccessorImpl.invoke(Unknown Source)
	at java.lang.reflect.Method.invoke(Unknown Source)
	at org.testng.internal.MethodInvocationHelper.invokeMethod(MethodInvocationHelper.java:80)
	at org.testng.internal.Invoker.invokeConfigurationMethod(Invoker.java:543)
	at org.testng.internal.Invoker.invokeConfigurations(Invoker.java:212)
	at org.testng.internal.Invoker.invokeMethod(Invoker.java:631)
	at org.testng.internal.Invoker.invokeTestMethod(Invoker.java:883)
	at org.testng.internal.Invoker.invokeTestMethods(Invoker.java:1208)
	at org.testng.internal.TestMethodWorker.invokeTestMethods(TestMethodWorker.java:127)
	at org.testng.internal.TestMethodWorker.run(TestMethodWorker.java:111)
	at org.testng.TestRunner.privateRun(TestRunner.java:758)
	at org.testng.TestRunner.run(TestRunner.java:613)
	at org.testng.SuiteRunner.runTest(SuiteRunner.java:334)
	at org.testng.SuiteRunner.runSequentially(SuiteRunner.java:329)
	at org.testng.SuiteRunner.privateRun(SuiteRunner.java:291)
	at org.testng.SuiteRunner.run(SuiteRunner.java:240)
	at org.testng.SuiteRunnerWorker.runSuite(SuiteRunnerWorker.java:53)
	at org.testng.SuiteRunnerWorker.run(SuiteRunnerWorker.java:87)
	at org.testng.TestNG.runSuitesSequentially(TestNG.java:1142)
	at org.testng.TestNG.runSuitesLocally(TestNG.java:1067)
	at org.testng.TestNG.run(TestNG.java:979)
	at org.testng.remote.RemoteTestNG.run(RemoteTestNG.java:109)
	at org.testng.remote.RemoteTestNG.initAndRun(RemoteTestNG.java:202)
	at org.testng.remote.RemoteTestNG.main(RemoteTestNG.java:173)
]]>
    </failure>
  </testcase>
  <testcase name="@AfterMethod afterTest" time="0.0" classname="test.cli.cloudify.BadUSMServiceDownAfterUninstallApplicationTest">
    <skipped/>
  </testcase>
  <testcase name="@BeforeMethod beforeTest" time="0.0" classname="test.cli.cloudify.BootstrapCloudEc2Test">
    <failure type="java.lang.AssertionError" message="bootstrap-cloud failed.">
      <![CDATA[java.lang.AssertionError: bootstrap-cloud failed.
	at org.testng.Assert.fail(Assert.java:89)
	at test.cli.cloudify.AbstractCloudEc2Test.beforeTest(AbstractCloudEc2Test.java:56)
	at sun.reflect.NativeMethodAccessorImpl.invoke0(Native Method)
	at sun.reflect.NativeMethodAccessorImpl.invoke(Unknown Source)
	at sun.reflect.DelegatingMethodAccessorImpl.invoke(Unknown Source)
	at java.lang.reflect.Method.invoke(Unknown Source)
	at org.testng.internal.MethodInvocationHelper.invokeMethod(MethodInvocationHelper.java:80)
	at org.testng.internal.Invoker.invokeConfigurationMethod(Invoker.java:543)
	at org.testng.internal.Invoker.invokeConfigurations(Invoker.java:212)
	at org.testng.internal.Invoker.invokeMethod(Invoker.java:631)
	at org.testng.internal.Invoker.invokeTestMethod(Invoker.java:883)
	at org.testng.internal.Invoker.invokeTestMethods(Invoker.java:1208)
	at org.testng.internal.TestMethodWorker.invokeTestMethods(TestMethodWorker.java:127)
	at org.testng.internal.TestMethodWorker.run(TestMethodWorker.java:111)
	at org.testng.TestRunner.privateRun(TestRunner.java:758)
	at org.testng.TestRunner.run(TestRunner.java:613)
	at org.testng.SuiteRunner.runTest(SuiteRunner.java:334)
	at org.testng.SuiteRunner.runSequentially(SuiteRunner.java:329)
	at org.testng.SuiteRunner.privateRun(SuiteRunner.java:291)
	at org.testng.SuiteRunner.run(SuiteRunner.java:240)
	at org.testng.SuiteRunnerWorker.runSuite(SuiteRunnerWorker.java:53)
	at org.testng.SuiteRunnerWorker.run(SuiteRunnerWorker.java:87)
	at org.testng.TestNG.runSuitesSequentially(TestNG.java:1142)
	at org.testng.TestNG.runSuitesLocally(TestNG.java:1067)
	at org.testng.TestNG.run(TestNG.java:979)
	at org.testng.remote.RemoteTestNG.run(RemoteTestNG.java:109)
	at org.testng.remote.RemoteTestNG.initAndRun(RemoteTestNG.java:202)
	at org.testng.remote.RemoteTestNG.main(RemoteTestNG.java:173)
]]>
    </failure>
  </testcase>
  <testcase name="@AfterMethod afterTest" time="0.0" classname="test.cli.cloudify.BootstrapCloudEc2Test">
    <skipped/>
  </testcase>
  <testcase name="@BeforeMethod beforeTest" time="0.0" classname="test.cli.cloudify.ConfigSlurperTest">
    <skipped/>
  </testcase>
  <testcase name="@AfterMethod afterTest" time="0.0" classname="test.cli.cloudify.ConfigSlurperTest">
    <skipped/>
  </testcase>
  <testcase name="@BeforeClass beforeClass" time="0.0" classname="test.cli.cloudify.CustomCommandsOnMultipleInstancesApplicationTest">
    <failure type="java.lang.AssertionError" message="In RunCommand: Process did not complete successfully">
      <![CDATA[java.lang.AssertionError: In RunCommand: Process did not complete successfully
	at org.testng.Assert.fail(Assert.java:89)
	at framework.utils.AssertUtils.AssertFail(AssertUtils.java:97)
	at framework.utils.AssertUtils.AssertFail(AssertUtils.java:89)
	at test.AbstractTest.AssertFail(AbstractTest.java:103)
	at test.cli.cloudify.CommandTestUtils.handleCliOutput(CommandTestUtils.java:111)
	at test.cli.cloudify.CommandTestUtils.runCommand(CommandTestUtils.java:51)
	at test.cli.cloudify.CommandTestUtils.runCommandAndWait(CommandTestUtils.java:123)
	at test.cli.cloudify.AbstractLocalCloudTest.runCommand(AbstractLocalCloudTest.java:212)
	at test.cli.cloudify.CustomCommandsOnMultipleInstancesApplicationTest.installApplication(CustomCommandsOnMultipleInstancesApplicationTest.java:234)
	at test.cli.cloudify.CustomCommandsOnMultipleInstancesApplicationTest.beforeClass(CustomCommandsOnMultipleInstancesApplicationTest.java:33)
	at sun.reflect.NativeMethodAccessorImpl.invoke0(Native Method)
	at sun.reflect.NativeMethodAccessorImpl.invoke(Unknown Source)
	at sun.reflect.DelegatingMethodAccessorImpl.invoke(Unknown Source)
	at java.lang.reflect.Method.invoke(Unknown Source)
	at org.testng.internal.MethodInvocationHelper.invokeMethod(MethodInvocationHelper.java:80)
	at org.testng.internal.Invoker.invokeConfigurationMethod(Invoker.java:543)
	at org.testng.internal.Invoker.invokeConfigurations(Invoker.java:212)
	at org.testng.internal.Invoker.invokeConfigurations(Invoker.java:138)
	at org.testng.internal.TestMethodWorker.invokeBeforeClassMethods(TestMethodWorker.java:175)
	at org.testng.internal.TestMethodWorker.run(TestMethodWorker.java:107)
	at org.testng.TestRunner.privateRun(TestRunner.java:758)
	at org.testng.TestRunner.run(TestRunner.java:613)
	at org.testng.SuiteRunner.runTest(SuiteRunner.java:334)
	at org.testng.SuiteRunner.runSequentially(SuiteRunner.java:329)
	at org.testng.SuiteRunner.privateRun(SuiteRunner.java:291)
	at org.testng.SuiteRunner.run(SuiteRunner.java:240)
	at org.testng.SuiteRunnerWorker.runSuite(SuiteRunnerWorker.java:53)
	at org.testng.SuiteRunnerWorker.run(SuiteRunnerWorker.java:87)
	at org.testng.TestNG.runSuitesSequentially(TestNG.java:1142)
	at org.testng.TestNG.runSuitesLocally(TestNG.java:1067)
	at org.testng.TestNG.run(TestNG.java:979)
	at org.testng.remote.RemoteTestNG.run(RemoteTestNG.java:109)
	at org.testng.remote.RemoteTestNG.initAndRun(RemoteTestNG.java:202)
	at org.testng.remote.RemoteTestNG.main(RemoteTestNG.java:173)
]]>
    </failure>
  </testcase>
  <testcase name="@AfterMethod afterTest" time="0.0" classname="test.cli.cloudify.CustomCommandsOnMultipleInstancesApplicationTest">
    <skipped/>
  </testcase>
  <testcase name="@AfterMethod afterTest" time="0.0" classname="test.cli.cloudify.CustomCommandsOnMultipleInstancesApplicationTest">
    <skipped/>
  </testcase>
  <testcase name="@AfterMethod afterTest" time="0.0" classname="test.cli.cloudify.CustomCommandsOnMultipleInstancesApplicationTest">
    <skipped/>
  </testcase>
  <testcase name="@AfterMethod afterTest" time="0.0" classname="test.cli.cloudify.CustomCommandsOnMultipleInstancesApplicationTest">
    <skipped/>
  </testcase>
  <testcase name="@AfterMethod afterTest" time="0.0" classname="test.cli.cloudify.CustomCommandsOnMultipleInstancesApplicationTest">
    <skipped/>
  </testcase>
  <testcase name="@AfterClass afterClass" time="0.0" classname="test.cli.cloudify.CustomCommandsOnMultipleInstancesApplicationTest">
    <skipped/>
  </testcase>
  <testcase name="@BeforeMethod beforeTest" time="0.0" classname="test.cli.cloudify.TestCLIRestExceptionHandling">
    <skipped/>
  </testcase>
  <testcase name="@AfterMethod afterTest" time="0.0" classname="test.cli.cloudify.TestCLIRestExceptionHandling">
    <skipped/>
  </testcase>
  <testcase name="@BeforeMethod beforeTest" time="0.0" classname="test.cli.cloudify.UninstallWithDelayTest">
    <skipped/>
  </testcase>
  <testcase name="@AfterMethod afterTest" time="0.0" classname="test.cli.cloudify.UninstallWithDelayTest">
    <skipped/>
  </testcase>
  <testcase name="@BeforeMethod beforeTest" time="0.0" classname="test.cli.cloudify.UninstallWithDelayTest">
    <skipped/>
  </testcase>
  <testcase name="@AfterMethod afterTest" time="0.0" classname="test.cli.cloudify.UninstallWithDelayTest">
    <skipped/>
  </testcase>
  <testcase name="@BeforeMethod beforeTest" time="0.0" classname="test.cli.cloudify.ConnectTest">
    <skipped/>
  </testcase>
  <testcase name="@AfterMethod afterTest" time="0.0" classname="test.cli.cloudify.ConnectTest">
    <skipped/>
  </testcase>
  <testcase name="@BeforeClass beforeClass" time="0.0" classname="test.cli.cloudify.CustomCommandsOnMultipleInstancesTest">
    <failure type="java.lang.AssertionError" message="In RunCommand: Process did not complete successfully">
      <![CDATA[java.lang.AssertionError: In RunCommand: Process did not complete successfully
	at org.testng.Assert.fail(Assert.java:89)
	at framework.utils.AssertUtils.AssertFail(AssertUtils.java:97)
	at framework.utils.AssertUtils.AssertFail(AssertUtils.java:89)
	at test.AbstractTest.AssertFail(AbstractTest.java:103)
	at test.cli.cloudify.CommandTestUtils.handleCliOutput(CommandTestUtils.java:111)
	at test.cli.cloudify.CommandTestUtils.runCommand(CommandTestUtils.java:51)
	at test.cli.cloudify.CommandTestUtils.runCommandAndWait(CommandTestUtils.java:123)
	at test.cli.cloudify.AbstractLocalCloudTest.runCommand(AbstractLocalCloudTest.java:212)
	at test.cli.cloudify.CustomCommandsOnMultipleInstancesTest.installService(CustomCommandsOnMultipleInstancesTest.java:227)
	at test.cli.cloudify.CustomCommandsOnMultipleInstancesTest.beforeClass(CustomCommandsOnMultipleInstancesTest.java:34)
	at sun.reflect.NativeMethodAccessorImpl.invoke0(Native Method)
	at sun.reflect.NativeMethodAccessorImpl.invoke(Unknown Source)
	at sun.reflect.DelegatingMethodAccessorImpl.invoke(Unknown Source)
	at java.lang.reflect.Method.invoke(Unknown Source)
	at org.testng.internal.MethodInvocationHelper.invokeMethod(MethodInvocationHelper.java:80)
	at org.testng.internal.Invoker.invokeConfigurationMethod(Invoker.java:543)
	at org.testng.internal.Invoker.invokeConfigurations(Invoker.java:212)
	at org.testng.internal.Invoker.invokeConfigurations(Invoker.java:138)
	at org.testng.internal.TestMethodWorker.invokeBeforeClassMethods(TestMethodWorker.java:175)
	at org.testng.internal.TestMethodWorker.run(TestMethodWorker.java:107)
	at org.testng.TestRunner.privateRun(TestRunner.java:758)
	at org.testng.TestRunner.run(TestRunner.java:613)
	at org.testng.SuiteRunner.runTest(SuiteRunner.java:334)
	at org.testng.SuiteRunner.runSequentially(SuiteRunner.java:329)
	at org.testng.SuiteRunner.privateRun(SuiteRunner.java:291)
	at org.testng.SuiteRunner.run(SuiteRunner.java:240)
	at org.testng.SuiteRunnerWorker.runSuite(SuiteRunnerWorker.java:53)
	at org.testng.SuiteRunnerWorker.run(SuiteRunnerWorker.java:87)
	at org.testng.TestNG.runSuitesSequentially(TestNG.java:1142)
	at org.testng.TestNG.runSuitesLocally(TestNG.java:1067)
	at org.testng.TestNG.run(TestNG.java:979)
	at org.testng.remote.RemoteTestNG.run(RemoteTestNG.java:109)
	at org.testng.remote.RemoteTestNG.initAndRun(RemoteTestNG.java:202)
	at org.testng.remote.RemoteTestNG.main(RemoteTestNG.java:173)
]]>
    </failure>
  </testcase>
  <testcase name="@AfterMethod afterTest" time="0.0" classname="test.cli.cloudify.CustomCommandsOnMultipleInstancesTest">
    <skipped/>
  </testcase>
  <testcase name="@AfterMethod afterTest" time="0.0" classname="test.cli.cloudify.CustomCommandsOnMultipleInstancesTest">
    <skipped/>
  </testcase>
  <testcase name="@AfterMethod afterTest" time="0.0" classname="test.cli.cloudify.CustomCommandsOnMultipleInstancesTest">
    <skipped/>
  </testcase>
  <testcase name="@AfterMethod afterTest" time="0.0" classname="test.cli.cloudify.CustomCommandsOnMultipleInstancesTest">
    <skipped/>
  </testcase>
  <testcase name="@AfterClass afterClass" time="0.0" classname="test.cli.cloudify.CustomCommandsOnMultipleInstancesTest">
    <skipped/>
  </testcase>
  <testcase name="@BeforeMethod beforeTest" time="0.0" classname="test.cli.cloudify.FailedToInstallServiceApplicationTest">
    <skipped/>
  </testcase>
  <testcase name="@AfterMethod afterTest" time="0.0" classname="test.cli.cloudify.FailedToInstallServiceApplicationTest">
    <skipped/>
  </testcase>
  <testcase name="@BeforeMethod beforeTest" time="0.0" classname="test.cli.cloudify.FailedToInstallServiceApplicationTest">
    <skipped/>
  </testcase>
  <testcase name="@AfterMethod afterTest" time="0.0" classname="test.cli.cloudify.FailedToInstallServiceApplicationTest">
    <skipped/>
  </testcase>
  <testcase name="@BeforeMethod beforeTest" time="0.0" classname="test.cli.cloudify.HttpStartDetectionTest">
    <skipped/>
  </testcase>
  <testcase name="@AfterMethod afterTest" time="0.0" classname="test.cli.cloudify.HttpStartDetectionTest">
    <skipped/>
  </testcase>
  <testcase name="@BeforeMethod beforeTest" time="0.0" classname="test.cli.cloudify.HttpStartDetectionTest">
    <skipped/>
  </testcase>
  <testcase name="@AfterMethod afterTest" time="0.0" classname="test.cli.cloudify.HttpStartDetectionTest">
    <skipped/>
  </testcase>
  <testcase name="testController" time="0.0" classname="test.cli.cloudify.AdminApiControllerTest">
    <skipped/>
  </testcase>
  <testcase name="badUsmServiceDownTest" time="0.0" classname="test.cli.cloudify.BadUSMServiceDownAfterUninstallApplicationTest">
    <skipped/>
  </testcase>
  <testcase name="bootstrapEc2CloudTest" time="0.0" classname="test.cli.cloudify.BootstrapCloudEc2Test">
    <skipped/>
  </testcase>
  <testcase name="test" time="0.0" classname="test.cli.cloudify.ConfigSlurperTest">
    <skipped/>
  </testcase>
  <testcase name="testContextCommand" time="0.0" classname="test.cli.cloudify.CustomCommandsOnMultipleInstancesApplicationTest">
    <skipped/>
  </testcase>
  <testcase name="testExceptionCommand" time="0.0" classname="test.cli.cloudify.CustomCommandsOnMultipleInstancesApplicationTest">
    <skipped/>
  </testcase>
  <testcase name="testParamsCommand" time="0.0" classname="test.cli.cloudify.CustomCommandsOnMultipleInstancesApplicationTest">
    <skipped/>
  </testcase>
  <testcase name="testPrintCommandOnApp" time="0.0" classname="test.cli.cloudify.CustomCommandsOnMultipleInstancesApplicationTest">
    <skipped/>
  </testcase>
  <testcase name="testRunScriptCommand" time="0.0" classname="test.cli.cloudify.CustomCommandsOnMultipleInstancesApplicationTest">
    <skipped/>
  </testcase>
  <testcase name="testInstallAndUninstall" time="1.703" classname="test.cli.cloudify.InstallAndUninstallApplicationTest">
    <failure type="java.lang.AssertionError" message="In RunCommand: Process did not complete successfully">
      <![CDATA[java.lang.AssertionError: In RunCommand: Process did not complete successfully
	at org.testng.Assert.fail(Assert.java:89)
	at framework.utils.AssertUtils.AssertFail(AssertUtils.java:97)
	at framework.utils.AssertUtils.AssertFail(AssertUtils.java:89)
	at test.AbstractTest.AssertFail(AbstractTest.java:103)
	at test.cli.cloudify.CommandTestUtils.handleCliOutput(CommandTestUtils.java:111)
	at test.cli.cloudify.CommandTestUtils.runCommand(CommandTestUtils.java:51)
	at test.cli.cloudify.CommandTestUtils.runCommandAndWait(CommandTestUtils.java:123)
	at test.cli.cloudify.AbstractLocalCloudTest.runCommand(AbstractLocalCloudTest.java:212)
	at test.cli.cloudify.InstallAndUninstallApplicationTest.doTest(InstallAndUninstallApplicationTest.java:31)
	at test.cli.cloudify.InstallAndUninstallApplicationTest.testInstallAndUninstall(InstallAndUninstallApplicationTest.java:23)
	at sun.reflect.NativeMethodAccessorImpl.invoke0(Native Method)
	at sun.reflect.NativeMethodAccessorImpl.invoke(Unknown Source)
	at sun.reflect.DelegatingMethodAccessorImpl.invoke(Unknown Source)
	at java.lang.reflect.Method.invoke(Unknown Source)
	at org.testng.internal.MethodInvocationHelper.invokeMethod(MethodInvocationHelper.java:80)
	at org.testng.internal.InvokeMethodRunnable.runOne(InvokeMethodRunnable.java:46)
	at org.testng.internal.InvokeMethodRunnable.run(InvokeMethodRunnable.java:37)
	at java.util.concurrent.Executors$RunnableAdapter.call(Unknown Source)
	at java.util.concurrent.FutureTask$Sync.innerRun(Unknown Source)
	at java.util.concurrent.FutureTask.run(Unknown Source)
	at java.util.concurrent.ThreadPoolExecutor$Worker.runTask(Unknown Source)
	at java.util.concurrent.ThreadPoolExecutor$Worker.run(Unknown Source)
	at java.lang.Thread.run(Unknown Source)
]]>
    </failure>
  </testcase>
  <testcase name="testDataGridRecipeInstall" time="1.25" classname="test.cli.cloudify.InstallAndUninstallServiceTest">
    <failure type="java.lang.AssertionError" message="In RunCommand: Process did not complete successfully">
      <![CDATA[java.lang.AssertionError: In RunCommand: Process did not complete successfully
	at org.testng.Assert.fail(Assert.java:89)
	at framework.utils.AssertUtils.AssertFail(AssertUtils.java:97)
	at framework.utils.AssertUtils.AssertFail(AssertUtils.java:89)
	at test.AbstractTest.AssertFail(AbstractTest.java:103)
	at test.cli.cloudify.CommandTestUtils.handleCliOutput(CommandTestUtils.java:111)
	at test.cli.cloudify.CommandTestUtils.runCommand(CommandTestUtils.java:51)
	at test.cli.cloudify.CommandTestUtils.runCommandAndWait(CommandTestUtils.java:123)
	at test.cli.cloudify.InstallAndUninstallServiceTest.testRestApiInstall(InstallAndUninstallServiceTest.java:73)
	at test.cli.cloudify.InstallAndUninstallServiceTest.testDataGridRecipeInstall(InstallAndUninstallServiceTest.java:62)
	at sun.reflect.NativeMethodAccessorImpl.invoke0(Native Method)
	at sun.reflect.NativeMethodAccessorImpl.invoke(Unknown Source)
	at sun.reflect.DelegatingMethodAccessorImpl.invoke(Unknown Source)
	at java.lang.reflect.Method.invoke(Unknown Source)
	at org.testng.internal.MethodInvocationHelper.invokeMethod(MethodInvocationHelper.java:80)
	at org.testng.internal.InvokeMethodRunnable.runOne(InvokeMethodRunnable.java:46)
	at org.testng.internal.InvokeMethodRunnable.run(InvokeMethodRunnable.java:37)
	at java.util.concurrent.Executors$RunnableAdapter.call(Unknown Source)
	at java.util.concurrent.FutureTask$Sync.innerRun(Unknown Source)
	at java.util.concurrent.FutureTask.run(Unknown Source)
	at java.util.concurrent.ThreadPoolExecutor$Worker.runTask(Unknown Source)
	at java.util.concurrent.ThreadPoolExecutor$Worker.run(Unknown Source)
	at java.lang.Thread.run(Unknown Source)
]]>
    </failure>
  </testcase>
  <testcase name="testMirrorRecipeInstall" time="1.219" classname="test.cli.cloudify.InstallAndUninstallServiceTest">
    <failure type="java.lang.AssertionError" message="In RunCommand: Process did not complete successfully">
      <![CDATA[java.lang.AssertionError: In RunCommand: Process did not complete successfully
	at org.testng.Assert.fail(Assert.java:89)
	at framework.utils.AssertUtils.AssertFail(AssertUtils.java:97)
	at framework.utils.AssertUtils.AssertFail(AssertUtils.java:89)
	at test.AbstractTest.AssertFail(AbstractTest.java:103)
	at test.cli.cloudify.CommandTestUtils.handleCliOutput(CommandTestUtils.java:111)
	at test.cli.cloudify.CommandTestUtils.runCommand(CommandTestUtils.java:51)
	at test.cli.cloudify.CommandTestUtils.runCommandAndWait(CommandTestUtils.java:123)
	at test.cli.cloudify.InstallAndUninstallServiceTest.testRestApiInstall(InstallAndUninstallServiceTest.java:73)
	at test.cli.cloudify.InstallAndUninstallServiceTest.testMirrorRecipeInstall(InstallAndUninstallServiceTest.java:67)
	at sun.reflect.NativeMethodAccessorImpl.invoke0(Native Method)
	at sun.reflect.NativeMethodAccessorImpl.invoke(Unknown Source)
	at sun.reflect.DelegatingMethodAccessorImpl.invoke(Unknown Source)
	at java.lang.reflect.Method.invoke(Unknown Source)
	at org.testng.internal.MethodInvocationHelper.invokeMethod(MethodInvocationHelper.java:80)
	at org.testng.internal.InvokeMethodRunnable.runOne(InvokeMethodRunnable.java:46)
	at org.testng.internal.InvokeMethodRunnable.run(InvokeMethodRunnable.java:37)
	at java.util.concurrent.Executors$RunnableAdapter.call(Unknown Source)
	at java.util.concurrent.FutureTask$Sync.innerRun(Unknown Source)
	at java.util.concurrent.FutureTask.run(Unknown Source)
	at java.util.concurrent.ThreadPoolExecutor$Worker.runTask(Unknown Source)
	at java.util.concurrent.ThreadPoolExecutor$Worker.run(Unknown Source)
	at java.lang.Thread.run(Unknown Source)
]]>
    </failure>
  </testcase>
  <testcase name="testServletInstall" time="1.328" classname="test.cli.cloudify.InstallAndUninstallServiceTest">
    <failure type="java.lang.AssertionError" message="In RunCommand: Process did not complete successfully">
      <![CDATA[java.lang.AssertionError: In RunCommand: Process did not complete successfully
	at org.testng.Assert.fail(Assert.java:89)
	at framework.utils.AssertUtils.AssertFail(AssertUtils.java:97)
	at framework.utils.AssertUtils.AssertFail(AssertUtils.java:89)
	at test.AbstractTest.AssertFail(AbstractTest.java:103)
	at test.cli.cloudify.CommandTestUtils.handleCliOutput(CommandTestUtils.java:111)
	at test.cli.cloudify.CommandTestUtils.runCommand(CommandTestUtils.java:51)
	at test.cli.cloudify.CommandTestUtils.runCommandAndWait(CommandTestUtils.java:123)
	at test.cli.cloudify.InstallAndUninstallServiceTest.testRestApiInstall(InstallAndUninstallServiceTest.java:73)
	at test.cli.cloudify.InstallAndUninstallServiceTest.testServletInstall(InstallAndUninstallServiceTest.java:42)
	at sun.reflect.NativeMethodAccessorImpl.invoke0(Native Method)
	at sun.reflect.NativeMethodAccessorImpl.invoke(Unknown Source)
	at sun.reflect.DelegatingMethodAccessorImpl.invoke(Unknown Source)
	at java.lang.reflect.Method.invoke(Unknown Source)
	at org.testng.internal.MethodInvocationHelper.invokeMethod(MethodInvocationHelper.java:80)
	at org.testng.internal.InvokeMethodRunnable.runOne(InvokeMethodRunnable.java:46)
	at org.testng.internal.InvokeMethodRunnable.run(InvokeMethodRunnable.java:37)
	at java.util.concurrent.Executors$RunnableAdapter.call(Unknown Source)
	at java.util.concurrent.FutureTask$Sync.innerRun(Unknown Source)
	at java.util.concurrent.FutureTask.run(Unknown Source)
	at java.util.concurrent.ThreadPoolExecutor$Worker.runTask(Unknown Source)
	at java.util.concurrent.ThreadPoolExecutor$Worker.run(Unknown Source)
	at java.lang.Thread.run(Unknown Source)
]]>
    </failure>
  </testcase>
  <testcase name="testServletRecipeInstall" time="1.343" classname="test.cli.cloudify.InstallAndUninstallServiceTest">
    <failure type="java.lang.AssertionError" message="In RunCommand: Process did not complete successfully">
      <![CDATA[java.lang.AssertionError: In RunCommand: Process did not complete successfully
	at org.testng.Assert.fail(Assert.java:89)
	at framework.utils.AssertUtils.AssertFail(AssertUtils.java:97)
	at framework.utils.AssertUtils.AssertFail(AssertUtils.java:89)
	at test.AbstractTest.AssertFail(AbstractTest.java:103)
	at test.cli.cloudify.CommandTestUtils.handleCliOutput(CommandTestUtils.java:111)
	at test.cli.cloudify.CommandTestUtils.runCommand(CommandTestUtils.java:51)
	at test.cli.cloudify.CommandTestUtils.runCommandAndWait(CommandTestUtils.java:123)
	at test.cli.cloudify.InstallAndUninstallServiceTest.testRestApiInstall(InstallAndUninstallServiceTest.java:73)
	at test.cli.cloudify.InstallAndUninstallServiceTest.testServletRecipeInstall(InstallAndUninstallServiceTest.java:52)
	at sun.reflect.NativeMethodAccessorImpl.invoke0(Native Method)
	at sun.reflect.NativeMethodAccessorImpl.invoke(Unknown Source)
	at sun.reflect.DelegatingMethodAccessorImpl.invoke(Unknown Source)
	at java.lang.reflect.Method.invoke(Unknown Source)
	at org.testng.internal.MethodInvocationHelper.invokeMethod(MethodInvocationHelper.java:80)
	at org.testng.internal.InvokeMethodRunnable.runOne(InvokeMethodRunnable.java:46)
	at org.testng.internal.InvokeMethodRunnable.run(InvokeMethodRunnable.java:37)
	at java.util.concurrent.Executors$RunnableAdapter.call(Unknown Source)
	at java.util.concurrent.FutureTask$Sync.innerRun(Unknown Source)
	at java.util.concurrent.FutureTask.run(Unknown Source)
	at java.util.concurrent.ThreadPoolExecutor$Worker.runTask(Unknown Source)
	at java.util.concurrent.ThreadPoolExecutor$Worker.run(Unknown Source)
	at java.lang.Thread.run(Unknown Source)
]]>
    </failure>
  </testcase>
  <testcase name="testStatefulRecipeInstall" time="1.453" classname="test.cli.cloudify.InstallAndUninstallServiceTest">
    <failure type="java.lang.AssertionError" message="In RunCommand: Process did not complete successfully">
      <![CDATA[java.lang.AssertionError: In RunCommand: Process did not complete successfully
	at org.testng.Assert.fail(Assert.java:89)
	at framework.utils.AssertUtils.AssertFail(AssertUtils.java:97)
	at framework.utils.AssertUtils.AssertFail(AssertUtils.java:89)
	at test.AbstractTest.AssertFail(AbstractTest.java:103)
	at test.cli.cloudify.CommandTestUtils.handleCliOutput(CommandTestUtils.java:111)
	at test.cli.cloudify.CommandTestUtils.runCommand(CommandTestUtils.java:51)
	at test.cli.cloudify.CommandTestUtils.runCommandAndWait(CommandTestUtils.java:123)
	at test.cli.cloudify.InstallAndUninstallServiceTest.testRestApiInstall(InstallAndUninstallServiceTest.java:73)
	at test.cli.cloudify.InstallAndUninstallServiceTest.testStatefulRecipeInstall(InstallAndUninstallServiceTest.java:57)
	at sun.reflect.NativeMethodAccessorImpl.invoke0(Native Method)
	at sun.reflect.NativeMethodAccessorImpl.invoke(Unknown Source)
	at sun.reflect.DelegatingMethodAccessorImpl.invoke(Unknown Source)
	at java.lang.reflect.Method.invoke(Unknown Source)
	at org.testng.internal.MethodInvocationHelper.invokeMethod(MethodInvocationHelper.java:80)
	at org.testng.internal.InvokeMethodRunnable.runOne(InvokeMethodRunnable.java:46)
	at org.testng.internal.InvokeMethodRunnable.run(InvokeMethodRunnable.java:37)
	at java.util.concurrent.Executors$RunnableAdapter.call(Unknown Source)
	at java.util.concurrent.FutureTask$Sync.innerRun(Unknown Source)
	at java.util.concurrent.FutureTask.run(Unknown Source)
	at java.util.concurrent.ThreadPoolExecutor$Worker.runTask(Unknown Source)
	at java.util.concurrent.ThreadPoolExecutor$Worker.run(Unknown Source)
	at java.lang.Thread.run(Unknown Source)
]]>
    </failure>
  </testcase>
  <testcase name="testUSMInstall" time="1.969" classname="test.cli.cloudify.InstallAndUninstallServiceTest">
    <failure type="java.lang.AssertionError" message="In RunCommand: Process did not complete successfully">
      <![CDATA[java.lang.AssertionError: In RunCommand: Process did not complete successfully
	at org.testng.Assert.fail(Assert.java:89)
	at framework.utils.AssertUtils.AssertFail(AssertUtils.java:97)
	at framework.utils.AssertUtils.AssertFail(AssertUtils.java:89)
	at test.AbstractTest.AssertFail(AbstractTest.java:103)
	at test.cli.cloudify.CommandTestUtils.handleCliOutput(CommandTestUtils.java:111)
	at test.cli.cloudify.CommandTestUtils.runCommand(CommandTestUtils.java:51)
	at test.cli.cloudify.CommandTestUtils.runCommandAndWait(CommandTestUtils.java:123)
	at test.cli.cloudify.InstallAndUninstallServiceTest.testRestApiInstall(InstallAndUninstallServiceTest.java:73)
	at test.cli.cloudify.InstallAndUninstallServiceTest.testUSMInstall(InstallAndUninstallServiceTest.java:47)
	at sun.reflect.NativeMethodAccessorImpl.invoke0(Native Method)
	at sun.reflect.NativeMethodAccessorImpl.invoke(Unknown Source)
	at sun.reflect.DelegatingMethodAccessorImpl.invoke(Unknown Source)
	at java.lang.reflect.Method.invoke(Unknown Source)
	at org.testng.internal.MethodInvocationHelper.invokeMethod(MethodInvocationHelper.java:80)
	at org.testng.internal.InvokeMethodRunnable.runOne(InvokeMethodRunnable.java:46)
	at org.testng.internal.InvokeMethodRunnable.run(InvokeMethodRunnable.java:37)
	at java.util.concurrent.Executors$RunnableAdapter.call(Unknown Source)
	at java.util.concurrent.FutureTask$Sync.innerRun(Unknown Source)
	at java.util.concurrent.FutureTask.run(Unknown Source)
	at java.util.concurrent.ThreadPoolExecutor$Worker.runTask(Unknown Source)
	at java.util.concurrent.ThreadPoolExecutor$Worker.run(Unknown Source)
	at java.lang.Thread.run(Unknown Source)
]]>
    </failure>
  </testcase>
  <testcase name="tomcatServiceDownAndCorruptedTest" time="1.313" classname="test.cli.cloudify.InternalUSMPuServiceDownTest">
    <failure type="java.lang.AssertionError" message="In RunCommand: Process did not complete successfully">
      <![CDATA[java.lang.AssertionError: In RunCommand: Process did not complete successfully
	at org.testng.Assert.fail(Assert.java:89)
	at framework.utils.AssertUtils.AssertFail(AssertUtils.java:97)
	at framework.utils.AssertUtils.AssertFail(AssertUtils.java:89)
	at test.AbstractTest.AssertFail(AbstractTest.java:103)
	at test.cli.cloudify.CommandTestUtils.handleCliOutput(CommandTestUtils.java:111)
	at test.cli.cloudify.CommandTestUtils.runCommand(CommandTestUtils.java:51)
	at test.cli.cloudify.CommandTestUtils.runCommandAndWait(CommandTestUtils.java:123)
	at test.cli.cloudify.InternalUSMPuServiceDownTest.tomcatServiceDownAndCorruptedTest(InternalUSMPuServiceDownTest.java:58)
	at sun.reflect.NativeMethodAccessorImpl.invoke0(Native Method)
	at sun.reflect.NativeMethodAccessorImpl.invoke(Unknown Source)
	at sun.reflect.DelegatingMethodAccessorImpl.invoke(Unknown Source)
	at java.lang.reflect.Method.invoke(Unknown Source)
	at org.testng.internal.MethodInvocationHelper.invokeMethod(MethodInvocationHelper.java:80)
	at org.testng.internal.InvokeMethodRunnable.runOne(InvokeMethodRunnable.java:46)
	at org.testng.internal.InvokeMethodRunnable.run(InvokeMethodRunnable.java:37)
	at java.util.concurrent.Executors$RunnableAdapter.call(Unknown Source)
	at java.util.concurrent.FutureTask$Sync.innerRun(Unknown Source)
	at java.util.concurrent.FutureTask.run(Unknown Source)
	at java.util.concurrent.ThreadPoolExecutor$Worker.runTask(Unknown Source)
	at java.util.concurrent.ThreadPoolExecutor$Worker.run(Unknown Source)
	at java.lang.Thread.run(Unknown Source)
]]>
    </failure>
  </testcase>
  <testcase name="testPetClinincApplication" time="126.561" classname="test.cli.cloudify.PetClinicApplicationTest">
    <failure type="java.lang.AssertionError" message="In RunCommand: Process did not complete successfully">
      <![CDATA[java.lang.AssertionError: In RunCommand: Process did not complete successfully
	at org.testng.Assert.fail(Assert.java:89)
	at framework.utils.AssertUtils.AssertFail(AssertUtils.java:97)
	at framework.utils.AssertUtils.AssertFail(AssertUtils.java:89)
	at test.AbstractTest.AssertFail(AbstractTest.java:103)
	at test.cli.cloudify.CommandTestUtils.handleCliOutput(CommandTestUtils.java:111)
	at test.cli.cloudify.CommandTestUtils.runCommand(CommandTestUtils.java:51)
	at test.cli.cloudify.CommandTestUtils.runCommandAndWait(CommandTestUtils.java:123)
	at test.cli.cloudify.PetClinicApplicationTest.testPetClinincApplication(PetClinicApplicationTest.java:57)
	at sun.reflect.NativeMethodAccessorImpl.invoke0(Native Method)
	at sun.reflect.NativeMethodAccessorImpl.invoke(Unknown Source)
	at sun.reflect.DelegatingMethodAccessorImpl.invoke(Unknown Source)
	at java.lang.reflect.Method.invoke(Unknown Source)
	at org.testng.internal.MethodInvocationHelper.invokeMethod(MethodInvocationHelper.java:80)
	at org.testng.internal.InvokeMethodRunnable.runOne(InvokeMethodRunnable.java:46)
	at org.testng.internal.InvokeMethodRunnable.run(InvokeMethodRunnable.java:37)
	at java.util.concurrent.Executors$RunnableAdapter.call(Unknown Source)
	at java.util.concurrent.FutureTask$Sync.innerRun(Unknown Source)
	at java.util.concurrent.FutureTask.run(Unknown Source)
	at java.util.concurrent.ThreadPoolExecutor$Worker.runTask(Unknown Source)
	at java.util.concurrent.ThreadPoolExecutor$Worker.run(Unknown Source)
	at java.lang.Thread.run(Unknown Source)
]]>
    </failure>
  </testcase>
  <testcase name="tomcatServiceDownAndCorruptedTest" time="2.219" classname="test.cli.cloudify.RepetitiveActualServiceFailoverTest">
    <failure type="java.lang.AssertionError" message="In RunCommand: Process did not complete successfully">
      <![CDATA[java.lang.AssertionError: In RunCommand: Process did not complete successfully
	at org.testng.Assert.fail(Assert.java:89)
	at framework.utils.AssertUtils.AssertFail(AssertUtils.java:97)
	at framework.utils.AssertUtils.AssertFail(AssertUtils.java:89)
	at test.AbstractTest.AssertFail(AbstractTest.java:103)
	at test.cli.cloudify.CommandTestUtils.handleCliOutput(CommandTestUtils.java:111)
	at test.cli.cloudify.CommandTestUtils.runCommand(CommandTestUtils.java:51)
	at test.cli.cloudify.CommandTestUtils.runCommandAndWait(CommandTestUtils.java:123)
	at test.cli.cloudify.RepetitiveActualServiceFailoverTest.tomcatServiceDownAndCorruptedTest(RepetitiveActualServiceFailoverTest.java:66)
	at sun.reflect.NativeMethodAccessorImpl.invoke0(Native Method)
	at sun.reflect.NativeMethodAccessorImpl.invoke(Unknown Source)
	at sun.reflect.DelegatingMethodAccessorImpl.invoke(Unknown Source)
	at java.lang.reflect.Method.invoke(Unknown Source)
	at org.testng.internal.MethodInvocationHelper.invokeMethod(MethodInvocationHelper.java:80)
	at org.testng.internal.InvokeMethodRunnable.runOne(InvokeMethodRunnable.java:46)
	at org.testng.internal.InvokeMethodRunnable.run(InvokeMethodRunnable.java:37)
	at java.util.concurrent.Executors$RunnableAdapter.call(Unknown Source)
	at java.util.concurrent.FutureTask$Sync.innerRun(Unknown Source)
	at java.util.concurrent.FutureTask.run(Unknown Source)
	at java.util.concurrent.ThreadPoolExecutor$Worker.runTask(Unknown Source)
	at java.util.concurrent.ThreadPoolExecutor$Worker.run(Unknown Source)
	at java.lang.Thread.run(Unknown Source)
]]>
    </failure>
  </testcase>
  <testcase name="testBadConnection" time="0.0" classname="test.cli.cloudify.TestCLIRestExceptionHandling">
    <skipped/>
  </testcase>
  <testcase name="testUninstallApplication" time="0.0" classname="test.cli.cloudify.UninstallWithDelayTest">
    <skipped/>
  </testcase>
  <testcase name="testUninstallService" time="0.0" classname="test.cli.cloudify.UninstallWithDelayTest">
    <skipped/>
  </testcase>
  <testcase name="testKitchenSink" time="1.89" classname="test.cli.cloudify.USMKitchenSinkTest">
    <failure type="java.lang.AssertionError" message="In RunCommand: Process did not complete successfully">
      <![CDATA[java.lang.AssertionError: In RunCommand: Process did not complete successfully
	at org.testng.Assert.fail(Assert.java:89)
	at framework.utils.AssertUtils.AssertFail(AssertUtils.java:97)
	at framework.utils.AssertUtils.AssertFail(AssertUtils.java:89)
	at test.AbstractTest.AssertFail(AbstractTest.java:103)
	at test.cli.cloudify.CommandTestUtils.handleCliOutput(CommandTestUtils.java:111)
	at test.cli.cloudify.CommandTestUtils.runCommand(CommandTestUtils.java:51)
	at test.cli.cloudify.CommandTestUtils.runCommandAndWait(CommandTestUtils.java:123)
	at test.cli.cloudify.AbstractLocalCloudTest.runCommand(AbstractLocalCloudTest.java:212)
	at test.cli.cloudify.USMKitchenSinkTest.installService(USMKitchenSinkTest.java:535)
	at test.cli.cloudify.USMKitchenSinkTest.testKitchenSink(USMKitchenSinkTest.java:73)
	at sun.reflect.NativeMethodAccessorImpl.invoke0(Native Method)
	at sun.reflect.NativeMethodAccessorImpl.invoke(Unknown Source)
	at sun.reflect.DelegatingMethodAccessorImpl.invoke(Unknown Source)
	at java.lang.reflect.Method.invoke(Unknown Source)
	at org.testng.internal.MethodInvocationHelper.invokeMethod(MethodInvocationHelper.java:80)
	at org.testng.internal.InvokeMethodRunnable.runOne(InvokeMethodRunnable.java:46)
	at org.testng.internal.InvokeMethodRunnable.run(InvokeMethodRunnable.java:37)
	at java.util.concurrent.Executors$RunnableAdapter.call(Unknown Source)
	at java.util.concurrent.FutureTask$Sync.innerRun(Unknown Source)
	at java.util.concurrent.FutureTask.run(Unknown Source)
	at java.util.concurrent.ThreadPoolExecutor$Worker.runTask(Unknown Source)
	at java.util.concurrent.ThreadPoolExecutor$Worker.run(Unknown Source)
	at java.lang.Thread.run(Unknown Source)
]]>
    </failure>
  </testcase>
  <testcase name="testRestConnect" time="0.0" classname="test.cli.cloudify.ConnectTest">
    <skipped/>
  </testcase>
  <testcase name="testContextCommand" time="0.0" classname="test.cli.cloudify.CustomCommandsOnMultipleInstancesTest">
    <skipped/>
  </testcase>
  <testcase name="testParamsCommand" time="0.0" classname="test.cli.cloudify.CustomCommandsOnMultipleInstancesTest">
    <skipped/>
  </testcase>
  <testcase name="testPrintCommand" time="0.0" classname="test.cli.cloudify.CustomCommandsOnMultipleInstancesTest">
    <skipped/>
  </testcase>
  <testcase name="testRunScriptCommand" time="0.016" classname="test.cli.cloudify.CustomCommandsOnMultipleInstancesTest">
    <skipped/>
  </testcase>
  <testcase name="testDetailsAndMonitorsMap" time="1.578" classname="test.cli.cloudify.LifecycleDetailsMonitorMapClosureTest">
    <failure type="java.lang.AssertionError" message="In RunCommand: Process did not complete successfully">
      <![CDATA[java.lang.AssertionError: In RunCommand: Process did not complete successfully
	at org.testng.Assert.fail(Assert.java:89)
	at framework.utils.AssertUtils.AssertFail(AssertUtils.java:97)
	at framework.utils.AssertUtils.AssertFail(AssertUtils.java:89)
	at test.AbstractTest.AssertFail(AbstractTest.java:103)
	at test.cli.cloudify.CommandTestUtils.handleCliOutput(CommandTestUtils.java:111)
	at test.cli.cloudify.CommandTestUtils.runCommand(CommandTestUtils.java:51)
	at test.cli.cloudify.CommandTestUtils.runCommandAndWait(CommandTestUtils.java:123)
	at test.cli.cloudify.AbstractLocalCloudTest.runCommand(AbstractLocalCloudTest.java:212)
	at test.cli.cloudify.LifecycleDetailsMonitorMapClosureTest.installService(LifecycleDetailsMonitorMapClosureTest.java:56)
	at test.cli.cloudify.LifecycleDetailsMonitorMapClosureTest.testDetailsAndMonitorsMap(LifecycleDetailsMonitorMapClosureTest.java:34)
	at sun.reflect.NativeMethodAccessorImpl.invoke0(Native Method)
	at sun.reflect.NativeMethodAccessorImpl.invoke(Unknown Source)
	at sun.reflect.DelegatingMethodAccessorImpl.invoke(Unknown Source)
	at java.lang.reflect.Method.invoke(Unknown Source)
	at org.testng.internal.MethodInvocationHelper.invokeMethod(MethodInvocationHelper.java:80)
	at org.testng.internal.InvokeMethodRunnable.runOne(InvokeMethodRunnable.java:46)
	at org.testng.internal.InvokeMethodRunnable.run(InvokeMethodRunnable.java:37)
	at java.util.concurrent.Executors$RunnableAdapter.call(Unknown Source)
	at java.util.concurrent.FutureTask$Sync.innerRun(Unknown Source)
	at java.util.concurrent.FutureTask.run(Unknown Source)
	at java.util.concurrent.ThreadPoolExecutor$Worker.runTask(Unknown Source)
	at java.util.concurrent.ThreadPoolExecutor$Worker.run(Unknown Source)
	at java.lang.Thread.run(Unknown Source)
]]>
    </failure>
  </testcase>
  <testcase name="testBadInstallApplication" time="0.0" classname="test.cli.cloudify.FailedToInstallServiceApplicationTest">
    <skipped/>
  </testcase>
  <testcase name="testBadInstallService" time="0.0" classname="test.cli.cloudify.FailedToInstallServiceApplicationTest">
    <skipped/>
  </testcase>
  <testcase name="testGroovyRuntimeExceptionHandling" time="1.312" classname="test.cli.cloudify.GroovyRuntimeExceptionInCliTest">
    <failure type="java.lang.AssertionError" message="Runtime exception was not printed by the CLI.">
      <![CDATA[java.lang.AssertionError: Runtime exception was not printed by the CLI.
	at org.testng.AssertJUnit.fail(AssertJUnit.java:59)
	at org.testng.AssertJUnit.assertTrue(AssertJUnit.java:24)
	at framework.utils.AssertUtils._assertTrue(AssertUtils.java:139)
	at framework.utils.AssertUtils.assertTrue(AssertUtils.java:132)
	at test.AbstractTest.assertTrue(AbstractTest.java:119)
	at test.cli.cloudify.GroovyRuntimeExceptionInCliTest.testGroovyRuntimeExceptionHandling(GroovyRuntimeExceptionInCliTest.java:39)
	at sun.reflect.NativeMethodAccessorImpl.invoke0(Native Method)
	at sun.reflect.NativeMethodAccessorImpl.invoke(Unknown Source)
	at sun.reflect.DelegatingMethodAccessorImpl.invoke(Unknown Source)
	at java.lang.reflect.Method.invoke(Unknown Source)
	at org.testng.internal.MethodInvocationHelper.invokeMethod(MethodInvocationHelper.java:80)
	at org.testng.internal.InvokeMethodRunnable.runOne(InvokeMethodRunnable.java:46)
	at org.testng.internal.InvokeMethodRunnable.run(InvokeMethodRunnable.java:37)
	at java.util.concurrent.Executors$RunnableAdapter.call(Unknown Source)
	at java.util.concurrent.FutureTask$Sync.innerRun(Unknown Source)
	at java.util.concurrent.FutureTask.run(Unknown Source)
	at java.util.concurrent.ThreadPoolExecutor$Worker.runTask(Unknown Source)
	at java.util.concurrent.ThreadPoolExecutor$Worker.run(Unknown Source)
	at java.lang.Thread.run(Unknown Source)
]]>
    </failure>
  </testcase>
  <testcase name="httpStartDetectionTest" time="0.0" classname="test.cli.cloudify.HttpStartDetectionTest">
    <skipped/>
  </testcase>
  <testcase name="urlLivenessDetectorTest" time="0.0" classname="test.cli.cloudify.HttpStartDetectionTest">
    <skipped/>
  </testcase>
</testsuite>
