<?xml version="1.0" encoding="UTF-8"?>
<!-- Generated by org.testng.reporters.JUnitReportReporter -->
<testsuite hostname="Noak-pc" name="test.cli.cloudify.GroovyRuntimeExceptionInCliTest" tests="1" failures="0" timestamp="2 Jan 2012 12:34:59 GMT" time="1.577" errors="1">
  <testcase name="testGroovyRuntimeExceptionHandling" time="1.577" classname="test.cli.cloudify.GroovyRuntimeExceptionInCliTest">
    <error type="java.lang.AssertionError" message="Runtime exception was not printed by the CLI.">
      <![CDATA[java.lang.AssertionError: Runtime exception was not printed by the CLI.
	at org.testng.AssertJUnit.fail(AssertJUnit.java:59)
	at org.testng.AssertJUnit.assertTrue(AssertJUnit.java:24)
	at framework.utils.AssertUtils._assertTrue(AssertUtils.java:139)
	at framework.utils.AssertUtils.assertTrue(AssertUtils.java:132)
	at test.AbstractTest.assertTrue(AbstractTest.java:119)
	at test.cli.cloudify.GroovyRuntimeExceptionInCliTest.testGroovyRuntimeExceptionHandling(GroovyRuntimeExceptionInCliTest.java:39)
	at sun.reflect.NativeMethodAccessorImpl.invoke0(Native Method)
	at sun.reflect.NativeMethodAccessorImpl.invoke(Unknown Source)
	at sun.reflect.DelegatingMethodAccessorImpl.invoke(Unknown Source)
	at java.lang.reflect.Method.invoke(Unknown Source)
	at org.testng.internal.MethodInvocationHelper.invokeMethod(MethodInvocationHelper.java:80)
	at org.testng.internal.InvokeMethodRunnable.runOne(InvokeMethodRunnable.java:46)
	at org.testng.internal.InvokeMethodRunnable.run(InvokeMethodRunnable.java:37)
	at java.util.concurrent.Executors$RunnableAdapter.call(Unknown Source)
	at java.util.concurrent.FutureTask$Sync.innerRun(Unknown Source)
	at java.util.concurrent.FutureTask.run(Unknown Source)
	at java.util.concurrent.ThreadPoolExecutor$Worker.runTask(Unknown Source)
	at java.util.concurrent.ThreadPoolExecutor$Worker.run(Unknown Source)
	at java.lang.Thread.run(Unknown Source)
]]>
    </error>
  </testcase>
</testsuite>
